<?xml version="1.0"?>
<robot name="DensoVS060v3">

<!-- <link name="world"/>

<joint name="world_to_base" type="fixed">
  <parent link="world"/>
  <child link="link0"/>
  <origin xyz="0 0 0.2" rpy="0 0 0"/>
</joint> -->

  <!-- Link 0 (base) -->
  <link name="link0">
    <visual>
      <geometry>
        <mesh filename="meshes/DensoVS060Link0.dae"/>
        <!-- <box size="0.05 0.05 0.2"/> -->
      </geometry>
    </visual>
  </link>

  <!-- Link 1 -->
  <link name="link1">
    <visual>
      <geometry>
        <mesh filename="meshes/DensoVS060Link1.dae"/>
        <!-- <box size="0.05 0.05 0.2"/> -->
      </geometry>
    </visual>
  </link>

  <!-- Joint 1 -->
  <joint name="joint1" type="revolute">
    <parent link="link0"/>
    <child link="link1"/>
    <!-- <origin xyz="0 0 0.148" rpy="1.5708 0 3.1416"/> -->
      <origin xyz="0 0 0.148" rpy="0 0 0"/>
    <axis xyz="0 0 1"/>
    <limit lower="-2.967" upper="2.967" effort="10" velocity="1"/>
  </joint>

  <!-- Link 2 -->
  <link name="link2">
    <visual>
      <geometry>
        <mesh filename="meshes/DensoVS060Link2.dae"/>
        <box size="0.05 0.05 0.2"/>
      </geometry>
    </visual>
  </link>

<link name="link1b" />
<joint name="link1_to_link1b" type="fixed">
  <parent link="link1"/>
  <child link="link1b"/>
  <origin xyz="0 0 0" rpy="-1.5708 0 0"/>
</joint>

<joint name="joint2" type="revolute">
  <parent link="link1b"/>
  <child link="link2"/>
  <origin xyz="0 0 0" rpy="0 0 -3.1416"/>
  <axis xyz="0 0 1"/>
  <limit lower="-2.0944" upper="2.0944" effort="10" velocity="1"/>
</joint>

  <!-- Joint 2
  <joint name="joint2" type="revolute">
    <parent link="link1"/>
    <child link="link2"/>
    <origin xyz="0 0 0" rpy="-1.5708 0 0"/>
    <axis xyz="0 0 1"/>
    <limit lower="-2.0944" upper="2.0944" effort="10" velocity="1"/>
  </joint> -->

  <!-- Link 3 -->
  <link name="link3">
    <visual>
      <geometry>
        <mesh filename="meshes/DensoVS060Link3.dae"/>
        <!-- <box size="0.05 0.05 0.2"/> -->
      </geometry>
    </visual>
  </link>

  <!-- Joint 3 -->
  <joint name="joint3" type="revolute">
    <parent link="link2"/>
    <child link="link3"/>
    <origin xyz="0 0.305 0" rpy="0 0 0"/>
    <axis xyz="0 0 1"/>
    <limit lower="-2.1817" upper="2.7053" effort="10" velocity="1"/>
  </joint>

  <!-- Link 4 -->
  <link name="link4">
    <visual>
      <geometry>
        <mesh filename="meshes/DensoVS060Link4.dae"/>
        <!-- <box size="0.05 0.05 0.2"/> -->
      </geometry>
    </visual>
  </link>

  <!-- Joint 4 -->
  <joint name="joint4" type="revolute">
    <parent link="link3"/>
    <child link="link4"/>
    <origin xyz="0 0 0" rpy="-1.5708 0 0"/>
    <axis xyz="0 0 1"/>
    <limit lower="-4.7124" upper="4.7124" effort="10" velocity="1"/>
  </joint>

  <!-- Link 5 -->
  <link name="link5">
    <visual>
      <geometry>
        <mesh filename="meshes/DensoVS060Link5.dae"/>
        <!-- <box size="0.05 0.05 0.2"/> -->
      </geometry>
    </visual>
  </link>

  <!-- Joint 5 -->
  <joint name="joint5" type="revolute">
    <parent link="link4"/>
    <child link="link5"/>
    <origin xyz="0 0 0.3" rpy="1.5708 0 0"/>
    <axis xyz="0 0 1"/>
    <limit lower="-2.0944" upper="2.0944" effort="10" velocity="1"/>
  </joint>

  <!-- Link 6 (end-effector) -->
  <link name="link6">
    <visual>
      <geometry>
        <mesh filename="meshes/DensoVS060Link6.dae"/>
        <!-- <box size="0.05 0.05 0.2"/> -->
      </geometry>
    </visual>
  </link>

  <!-- Joint 6 -->
  <joint name="joint6" type="revolute">
    <parent link="link5"/>
    <child link="link6"/>
    <origin xyz="0 0.06 0" rpy="-1.5708 0 0"/>
    <axis xyz="0 0 1"/>
    <limit lower="-6.2832" upper="6.2832" effort="10" velocity="1"/>
  </joint>

</robot>
