<?xml version='1.0' encoding='UTF-8'?>
<robot name="vega-1">
  <link name="base">
    <inertial>
      <origin xyz="0.01375 0.00093 0.11383" rpy="0 0 0" />
      <mass value="31.81396" />
      <inertia ixx="0.38398" ixy="-0.0005" ixz="-0.03043" iyy="0.39274" iyz="-8.43795E-06" izz="0.68293" />
    </inertial>
    <visual>
      <origin xyz="0 0 0" rpy="0 0 0" />
      <geometry>
        <mesh filename="meshes/visual/base.glb" />
      </geometry>
    </visual>
    </link>
  <link name="B_wheel_l1">
    <inertial>
      <origin xyz="-0.00642 0.00016 -0.01986" rpy="0 0 0" />
      <mass value="0.08321" />
      <inertia ixx="4.86774E-05" ixy="-1.39149E-07" ixz="-9.44514E-06" iyy="4.56083E-05" iyz="4.27003E-07" izz="5.42654E-05" />
    </inertial>
    <visual>
      <origin xyz="0 0 0" rpy="0 0 0" />
      <geometry>
        <mesh filename="meshes/visual/B_wheel_l1.glb" />
      </geometry>
    </visual>
  </link>
  <joint name="B_wheel_j1" type="continuous">
    <origin xyz="-0.265 0 0.044" rpy="0 0 0" />
    <parent link="base" />
    <child link="B_wheel_l1" />
    <axis xyz="0 0 -1" />
  </joint>
  <link name="B_wheel_l2">
    <inertial>
      <origin xyz="-0.00068 -0.01498 6.93889E-18" rpy="0 0 0" />
      <mass value="0.13625" />
      <inertia ixx="6.1102E-05" ixy="1.89907E-06" ixz="1.41126E-22" iyy="0.0001" iyz="3.12122E-21" izz="6.10162E-05" />
    </inertial>
    <visual>
      <origin xyz="0 0 0" rpy="0 0 0" />
      <geometry>
        <mesh filename="meshes/visual/B_wheel_l2.glb" />
      </geometry>
    </visual>
    </link>
  <joint name="B_wheel_j2" type="continuous">
    <origin xyz="-0.03329 0.01652 -0.058" rpy="0 0 0" />
    <parent link="B_wheel_l1" />
    <child link="B_wheel_l2" />
    <axis xyz="0.04517 0.99898 0" />
  </joint>
  <link name="R_wheel_l1">
    <inertial>
      <origin xyz="7.45834E-05 0.03713 -0.03504" rpy="0 0 0" />
      <mass value="0.16178" />
      <inertia ixx="0.0003" ixy="6.88081E-08" ixz="-4.89196E-07" iyy="0.00026" iyz="9.85221E-05" izz="0.00016" />
    </inertial>
    <visual>
      <origin xyz="0 0 0" rpy="0 0 3.14159" />
      <geometry>
        <mesh filename="meshes/visual/wheel_l1.glb" />
      </geometry>
    </visual>
  </link>
  <joint name="R_wheel_j1" type="revolute">
    <origin xyz="0.185 -0.225 0.133" rpy="0 0 0" />
    <parent link="base" />
    <child link="R_wheel_l1" />
    <axis xyz="0 0 -1" />
    <limit lower="-2.722" upper="2.722" effort="6" velocity="3" />
  </joint>
  <link name="R_wheel_l2">
    <inertial>
      <origin xyz="-7.83171E-18 -0.03937 0" rpy="0 0 0" />
      <mass value="1.21914" />
      <inertia ixx="0.00223" ixy="3.54778E-19" ixz="1.7577E-20" iyy="0.00376" iyz="-8.85953E-20" izz="0.00223" />
    </inertial>
    <visual>
      <origin xyz="0 0 0" rpy="0 0 3.14159" />
      <geometry>
        <mesh filename="meshes/visual/wheel_l2.glb" />
      </geometry>
    </visual>
    </link>
  <joint name="R_wheel_j2" type="continuous">
    <origin xyz="0 0.0395 -0.1005" rpy="0 0 0" />
    <parent link="R_wheel_l1" />
    <child link="R_wheel_l2" />
    <axis xyz="0 -1 0" />
    <limit effort="16" velocity="12" />
  </joint>
  <link name="L_wheel_l1">
    <inertial>
      <origin xyz="-7.45834E-05 -0.03713 -0.03504" rpy="0 0 0" />
      <mass value="0.16178" />
      <inertia ixx="0.0003" ixy="6.88081E-08" ixz="4.89196E-07" iyy="0.00026" iyz="-9.85221E-05" izz="0.00016" />
    </inertial>
    <visual>
      <origin xyz="0 0 0" rpy="0 0 0" />
      <geometry>
        <mesh filename="meshes/visual/wheel_l1.glb" />
      </geometry>
    </visual>
  </link>
  <joint name="L_wheel_j1" type="revolute">
    <origin xyz="0.185 0.225 0.133" rpy="0 0 0" />
    <parent link="base" />
    <child link="L_wheel_l1" />
    <axis xyz="0 0 -1" />
    <limit lower="-2.722" upper="2.722" effort="6" velocity="3" />
  </joint>
  <link name="L_wheel_l2">
    <inertial>
      <origin xyz="-1.64965E-17 0.03937 0" rpy="0 0 0" />
      <mass value="1.21914" />
      <inertia ixx="0.00223" ixy="-6.15518E-19" ixz="-1.76803E-20" iyy="0.00376" iyz="-1.66647E-19" izz="0.00223" />
    </inertial>
    <visual>
      <origin xyz="0 0 0" rpy="0 0 0" />
      <geometry>
        <mesh filename="meshes/visual/wheel_l2.glb" />
      </geometry>
    </visual>
    </link>
  <joint name="L_wheel_j2" type="continuous">
    <origin xyz="0 -0.0395 -0.1005" rpy="0 0 0" />
    <parent link="L_wheel_l1" />
    <child link="L_wheel_l2" />
    <axis xyz="0 1 0" />
    <limit effort="16" velocity="12" />
  </joint>
  <link name="torso_l1">
    <inertial>
      <origin xyz="0.17712 -0.06463 0.03987" rpy="0 0 0" />
      <mass value="2.84914" />
      <inertia ixx="0.01062" ixy="-0.00022" ixz="-0.01093" iyy="0.07152" iyz="-0.00018" izz="0.067" />
    </inertial>
    <visual>
      <origin xyz="0 0 0" rpy="0 0 0" />
      <geometry>
        <mesh filename="meshes/visual/torso_l1.glb" />
      </geometry>
    </visual>
    </link>
  <joint name="torso_j1" type="revolute">
    <origin xyz="-0.235 0.08 0.248" rpy="0 0 0" />
    <parent link="base" />
    <child link="torso_l1" />
    <axis xyz="0 -1 0" />
    <limit lower="0" upper="1.570" effort="700" velocity="0.9" />
  </joint>
  <link name="torso_l2">
    <inertial>
      <origin xyz="-0.19819 -0.02173 0.04732" rpy="0 0 0" />
      <mass value="2.07381" />
      <inertia ixx="0.00776" ixy="-0.00013" ixz="0.01024" iyy="0.05911" iyz="3.13396E-05" izz="0.05463" />
    </inertial>
    <visual>
      <origin xyz="0 0 0" rpy="0 0 0" />
      <geometry>
        <mesh filename="meshes/visual/torso_l2.glb" />
      </geometry>
    </visual>
    </link>
  <joint name="torso_j2" type="revolute">
    <origin xyz="0.396 -0.06 0.082" rpy="0 0 0" />
    <parent link="torso_l1" />
    <child link="torso_l2" />
    <axis xyz="0 1 0" />
    <limit lower="0" upper="3.141" effort="380" velocity="0.9" />
  </joint>
  <link name="torso_l3">
    <inertial>
      <origin xyz="-0.05623 -0.08424 0.25675" rpy="0 0 0" />
      <mass value="2.30133" />
      <inertia ixx="0.04617" ixy="-0.00102" ixz="0.00625" iyy="0.04404" iyz="0.00474" izz="0.01142" />
    </inertial>
    <visual>
      <origin xyz="0 0 0" rpy="0 0 0" />
      <geometry>
        <mesh filename="meshes/visual/torso_l3.glb" />
      </geometry>
    </visual>
    </link>
  <joint name="torso_j3" type="revolute">
    <origin xyz="-0.40718 0.058 0.09764" rpy="0 0 0" />
    <parent link="torso_l2" />
    <child link="torso_l3" />
    <axis xyz="0 -1 0" />
    <limit lower="-1.570" upper="1.570" effort="380" velocity="0.9" />
  </joint>
  <link name="head_l1">
    <inertial>
      <origin xyz="1.30097E-05 0.07221 -0.02629" rpy="0 0 0" />
      <mass value="0.2189" />
      <inertia ixx="0.00022" ixy="7.12442E-09" ixz="3.58817E-08" iyy="0.00012" iyz="-5.05425E-07" izz="0.00026" />
    </inertial>
    <visual>
      <origin xyz="0 0 0" rpy="0 0 0" />
      <geometry>
        <mesh filename="meshes/visual/head_l1.glb" />
      </geometry>
    </visual>
    </link>
  <joint name="head_j1" type="revolute">
    <origin xyz="-0.13258 -0.1505 0.45928" rpy="0 0 0" />
    <parent link="torso_l3" />
    <child link="head_l1" />
    <axis xyz="0 1 0" />
    <limit lower="-1.483" upper="1.483" effort="6" velocity="3.2" />
  </joint>
  <link name="head_l2">
    <inertial>
      <origin xyz="3.533E-05 0.01618 0.03389" rpy="0 0 0" />
      <mass value="0.21704" />
      <inertia ixx="0.00019" ixy="2.8808E-08" ixz="-7.0744E-09" iyy="0.00014" iyz="-3.60005E-05" izz="0.00018" />
    </inertial>
    <visual>
      <origin xyz="0 0 0" rpy="0 0 0" />
      <geometry>
        <mesh filename="meshes/visual/head_l2.glb" />
      </geometry>
    </visual>
    </link>
  <joint name="head_j2" type="revolute">
    <origin xyz="0 0.0725 -0.0035" rpy="0 0 0" />
    <parent link="head_l1" />
    <child link="head_l2" />
    <axis xyz="0 0 1" />
    <limit lower="-2.792" upper="2.792" effort="2.5" velocity="3.2" />
  </joint>
  <link name="head_l3">
    <inertial>
      <origin xyz="0.00816 -0.00315 0.03745" rpy="0 0 0" />
      <mass value="0.22599" />
      <inertia ixx="0.00029" ixy="-7.97223E-07" ixz="-3.47802E-06" iyy="0.00012" iyz="-3.24875E-06" izz="0.00028" />
    </inertial>
    <visual>
      <origin xyz="0 0 0" rpy="0 0 0" />
      <geometry>
        <mesh filename="meshes/visual/head_l3.glb" />
      </geometry>
    </visual>
    </link>
  <joint name="head_j3" type="revolute">
    <origin xyz="0 0.002 0.0495" rpy="0 0 0" />
    <parent link="head_l2" />
    <child link="head_l3" />
    <axis xyz="0 -1 0" />
    <limit lower="-1.378" upper="1.483" effort="6" velocity="3.2" />
  </joint>
  <link name="zed_depth_frame" />
  <joint name="zed_left_depth_mount" type="fixed">
    <origin xyz="0.025 0.023 0.0489" rpy="-1.57079 0 -1.57079" />
    <parent link="head_l3" />
    <child link="zed_depth_frame" />
    <axis xyz="0 0 0" />
  </joint>
  
  <link name="zed_left_camera" />
  <joint name="zed_left_camera_mount" type="fixed">
    <origin xyz="0.0365 0.023 0.0489" rpy="-1.57079 0 -1.57079" />
    <parent link="head_l3" />
    <child link="zed_left_camera" />
    <axis xyz="0 0 0" />
  </joint>
  <link name="zed_right_camera" />
  <joint name="zed_right_camera_mount" type="fixed">
    <origin xyz="0.0365 -0.027 0.0489" rpy="-1.57079 0 -1.57079" />
    <parent link="head_l3" />
    <child link="zed_right_camera" />
    <axis xyz="0 0 0" />
  </joint>

  <link name="L_arm_l1">
    <inertial>
      <origin xyz="0.0285 0.05287 0.00576" rpy="0 0 0" />
      <mass value="0.24689" />
      <inertia ixx="0.00019" ixy="-1.14453E-05" ixz="4.73162E-07" iyy="0.00022" iyz="-1.887E-07" izz="0.00033" />
    </inertial>
    <visual>
      <origin xyz="0 0 0" rpy="0 0 0" />
      <geometry>
        <mesh filename="meshes/visual/L_arm_l1.glb" />
      </geometry>
    </visual>
    </link>
  <joint name="L_arm_j1" type="revolute">
    <origin xyz="-0.05908 0.09146 0.44528" rpy="0 0 0" />
    <parent link="torso_l3" />
    <child link="L_arm_l1" />
    <axis xyz="0 1 0" />
    <limit lower="-3.071" upper="3.071" effort="150" velocity="2.4" />
  </joint>
  <link name="L_arm_l2">
    <inertial>
      <origin xyz="0.08194 -1.45468E-06 -0.04058" rpy="0 0 0" />
      <mass value="0.17057" />
      <inertia ixx="0.00016" ixy="1.21422E-10" ixz="2.8552E-06" iyy="0.00035" iyz="5.44743E-10" izz="0.0004" />
    </inertial>
    <visual>
      <origin xyz="0 0 0" rpy="0 0 0" />
      <geometry>
        <mesh filename="meshes/visual/arm_l2.glb" />
      </geometry>
    </visual>
    </link>
  <joint name="L_arm_j2" type="revolute">
    <origin xyz="0.04 0.06 0.0454" rpy="0 0 0" />
    <parent link="L_arm_l1" />
    <child link="L_arm_l2" />
    <axis xyz="0 0 1" />
    <limit lower="-0.453" upper="1.553" effort="150" velocity="2.4" />
  </joint>
  <link name="L_arm_l3">
    <inertial>
      <origin xyz="0.07978 0.00403 0.0398" rpy="0 0 0" />
      <mass value="0.2299" />
      <inertia ixx="0.00019" ixy="1.3436E-06" ixz="-6.62122E-05" iyy="0.00038" iyz="1.39597E-06" izz="0.00025" />
    </inertial>
    <visual>
      <origin xyz="0 0 0" rpy="0 0 0" />
      <geometry>
        <mesh filename="meshes/visual/arm_l3.glb" />
      </geometry>
    </visual>
    </link>
  <joint name="L_arm_j3" type="revolute">
    <origin xyz="0.1644 0 -0.043" rpy="0 0 0" />
    <parent link="L_arm_l2" />
    <child link="L_arm_l3" />
    <axis xyz="1 0 0" />
    <limit lower="-3.071" upper="3.071" effort="80" velocity="2.7" />
  </joint>
  <link name="L_arm_l4">
    <inertial>
      <origin xyz="0.09219 -0.03791 -0.02953" rpy="0 0 0" />
      <mass value="0.28335" />
      <inertia ixx="0.00025" ixy="1.2867E-05" ixz="0.00011" iyy="0.00065" iyz="-1.60044E-05" izz="0.00055" />
    </inertial>
    <visual>
      <origin xyz="0 0 0" rpy="0 0 0" />
      <geometry>
        <mesh filename="meshes/visual/arm_l4.glb" />
      </geometry>
    </visual>
    </link>
  <joint name="L_arm_j4" type="revolute">
    <origin xyz="0.113 0.0433 0.06" rpy="0 0 0" />
    <parent link="L_arm_l3" />
    <child link="L_arm_l4" />
    <axis xyz="0 1 0" />
    <limit lower="-3.071" upper="0.244" effort="80" velocity="2.7" />
  </joint>
  <link name="L_arm_l5">
    <inertial>
      <origin xyz="0.06497 -0.00266 1.20027E-05" rpy="0 0 0" />
      <mass value="0.21021" />
      <inertia ixx="0.00011" ixy="3.08906E-06" ixz="-5.18729E-08" iyy="0.00014" iyz="1.5559E-08" izz="0.00014" />
    </inertial>
    <visual>
      <origin xyz="0 0 0" rpy="0 0 0" />
      <geometry>
        <mesh filename="meshes/visual/arm_l5.glb" />
      </geometry>
    </visual>
    </link>
  <joint name="L_arm_j5" type="revolute">
    <origin xyz="0.1938 -0.0434 -0.04" rpy="0 0 0" />
    <parent link="L_arm_l4" />
    <child link="L_arm_l5" />
    <axis xyz="1 0 0" />
    <limit lower="-3.071" upper="3.071" effort="25" velocity="2.7" />
  </joint>
  <link name="L_arm_l6">
    <inertial>
      <origin xyz="0.05526 -0.02615 -0.00267" rpy="0 0 0" />
      <mass value="0.20526" />
      <inertia ixx="0.00011" ixy="1.81134E-05" ixz="6.68986E-07" iyy="0.00015" iyz="-5.22269E-07" izz="0.00014" />
    </inertial>
    <visual>
      <origin xyz="0 0 0" rpy="0 0 0" />
      <geometry>
        <mesh filename="meshes/visual/L_arm_l6.glb" />
      </geometry>
    </visual>
    </link>
  <joint name="L_arm_j6" type="revolute">
    <origin xyz="0.0762 0.0319 0" rpy="0 0 0" />
    <parent link="L_arm_l5" />
    <child link="L_arm_l6" />
    <axis xyz="0 1 0" />
    <limit lower="-1.396" upper="1.396" effort="25" velocity="2.7" />
  </joint>
  <link name="L_arm_l7">
    <inertial>
      <origin xyz="0.032 5.48376E-05 -0.01786" rpy="0 0 0" />
      <mass value="0.06296" />
      <inertia ixx="3.85975E-05" ixy="-6.27756E-09" ixz="6.5825E-06" iyy="4.0247E-05" iyz="-7.37881E-09" izz="5.84186E-05" />
    </inertial>
    <visual>
      <origin xyz="0 0 0" rpy="0 0 0" />
      <geometry>
        <mesh filename="meshes/visual/arm_l7.glb" />
      </geometry>
    </visual>
    </link>
  <joint name="L_arm_j7" type="revolute">
    <origin xyz="0.065 -0.032 0.0319" rpy="0 0 0" />
    <parent link="L_arm_l6" />
    <child link="L_arm_l7" />
    <axis xyz="0 0 1" />
    <limit lower="-1.378" upper="1.117" effort="25" velocity="2.7" />
  </joint>
  <link name="L_arm_l8">
    <inertial>
      <origin xyz="-0.01782 -0.00021 0.00027" rpy="0 0 0" />
      <mass value="0.07431" />
      <inertia ixx="3.42446E-05" ixy="2.93402E-08" ixz="1.26617E-07" iyy="2.12153E-05" iyz="8.02183E-08" izz="2.10214E-05" />
    </inertial>
    <visual>
      <origin xyz="0 0 0" rpy="0 -1.57079 0" />
      <geometry>
        <mesh filename="meshes/visual/arm_l8.glb" />
      </geometry>
    </visual>
    </link>
  <joint name="L_arm_j8" type="fixed">
    <origin xyz="0.11597 0 -0.032" rpy="0 1.57079 0" />
    <parent link="L_arm_l7" />
    <child link="L_arm_l8" />
    <axis xyz="0 0 0" />
  </joint>
  <link name="L_ee" />
  <joint name="L_ee_j0" type="fixed">
    <origin xyz="0 0 0" rpy="0 0 -1.57079" />
    <parent link="L_arm_l8" />
    <child link="L_ee" />
  </joint>

  <link name="R_arm_l1">
    <inertial>
      <origin xyz="0.02833 -0.05 0.0054" rpy="0 0 0" />
      <mass value="0.26325" />
      <inertia ixx="0.00027" ixy="4.79246E-05" ixz="4.58885E-07" iyy="0.00024" iyz="-1.88653E-07" izz="0.00043" />
    </inertial>
    <visual>
      <origin xyz="0 0 0" rpy="0 0 0" />
      <geometry>
        <mesh filename="meshes/visual/R_arm_l1.glb" />
      </geometry>
    </visual>
    </link>
  <joint name="R_arm_j1" type="revolute">
    <origin xyz="-0.05908 -0.24746 0.44528" rpy="0 0 0" />
    <parent link="torso_l3" />
    <child link="R_arm_l1" />
    <axis xyz="0 -1 0" />
    <limit lower="-3.071" upper="3.071" effort="150" velocity="2.4" />
  </joint>
  <link name="R_arm_l2">
    <inertial>
      <origin xyz="0.08749 -1.34526E-06 -0.04135" rpy="0 0 0" />
      <mass value="0.18345" />
      <inertia ixx="0.00017" ixy="1.41671E-10" ixz="2.88819E-06" iyy="0.00036" iyz="5.62291E-11" izz="0.00041" />
    </inertial>
    <visual>
      <origin xyz="0 0 0" rpy="0 0 0" />
      <geometry>
        <mesh filename="meshes/visual/arm_l2.glb" />
      </geometry>
    </visual>
    </link>
  <joint name="R_arm_j2" type="revolute">
    <origin xyz="0.04 -0.06 0.0454" rpy="0 0 0" />
    <parent link="R_arm_l1" />
    <child link="R_arm_l2" />
    <axis xyz="0 0 1" />
    <limit lower="-1.553" upper="0.453" effort="150" velocity="2.4" />
  </joint>
  <link name="R_arm_l3">
    <inertial>
      <origin xyz="0.08127 0.00414 0.04053" rpy="0 0 0" />
      <mass value="0.22384" />
      <inertia ixx="0.00019" ixy="1.41946E-06" ixz="-6.59147E-05" iyy="0.00038" iyz="8.3059E-07" izz="0.00025" />
    </inertial>
    <visual>
      <origin xyz="0 0 0" rpy="0 0 0" />
      <geometry>
        <mesh filename="meshes/visual/arm_l3.glb" />
      </geometry>
    </visual>
    </link>
  <joint name="R_arm_j3" type="revolute">
    <origin xyz="0.1644 0 -0.043" rpy="0 0 0" />
    <parent link="R_arm_l2" />
    <child link="R_arm_l3" />
    <axis xyz="1 0 0" />
    <limit lower="-3.071" upper="3.071" effort="80" velocity="2.7" />
  </joint>
  <link name="R_arm_l4">
    <inertial>
      <origin xyz="0.07728 -0.03736 -0.02906" rpy="0 0 0" />
      <mass value="0.25609" />
      <inertia ixx="0.00027" ixy="1.83596E-05" ixz="0.00011" iyy="0.00065" iyz="-2.72687E-05" izz="0.00055" />
    </inertial>
    <visual>
      <origin xyz="0 0 0" rpy="0 0 0" />
      <geometry>
        <mesh filename="meshes/visual/arm_l4.glb" />
      </geometry>
    </visual>
    </link>
  <joint name="R_arm_j4" type="revolute">
    <origin xyz="0.113 0.0433 0.06" rpy="0 0 0" />
    <parent link="R_arm_l3" />
    <child link="R_arm_l4" />
    <axis xyz="0 1 0" />
    <limit lower="-3.071" upper="0.244" effort="80" velocity="2.7" />
  </joint>
  <link name="R_arm_l5">
    <inertial>
      <origin xyz="0.06457 0.0025 -1.30383E-05" rpy="0 0 0" />
      <mass value="0.21223" />
      <inertia ixx="0.00011" ixy="-2.93839E-06" ixz="5.82462E-08" iyy="0.00014" iyz="9.77062E-09" izz="0.00014" />
    </inertial>
    <visual>
      <origin xyz="0 0 0" rpy="3.14159 0 0" />
      <geometry>
        <mesh filename="meshes/visual/arm_l5.glb" />
      </geometry>
    </visual>
    </link>
  <joint name="R_arm_j5" type="revolute">
    <origin xyz="0.1938 -0.0434 -0.04" rpy="0 0 0" />
    <parent link="R_arm_l4" />
    <child link="R_arm_l5" />
    <axis xyz="1 0 0" />
    <limit lower="-3.071" upper="3.071" effort="25" velocity="2.7" />
  </joint>
  <link name="R_arm_l6">
    <inertial>
      <origin xyz="0.05525 0.02614 -0.00267" rpy="0 0 0" />
      <mass value="0.20508" />
      <inertia ixx="0.00011" ixy="-1.81743E-05" ixz="6.89091E-07" iyy="0.00015" iyz="5.4206E-07" izz="0.00014" />
    </inertial>
    <visual>
      <origin xyz="0 0 0" rpy="0 0 0" />
      <geometry>
        <mesh filename="meshes/visual/R_arm_l6.glb" />
      </geometry>
    </visual>
    </link>
  <joint name="R_arm_j6" type="revolute">
    <origin xyz="0.0762 -0.0319 0" rpy="0 0 0" />
    <parent link="R_arm_l5" />
    <child link="R_arm_l6" />
    <axis xyz="0 -1 0" />
    <limit lower="-1.396" upper="1.396" effort="25" velocity="2.7" />
  </joint>
  <link name="R_arm_l7">
    <inertial>
      <origin xyz="0.03048 5.11736E-05 -0.01709" rpy="0 0 0" />
      <mass value="0.06731" />
      <inertia ixx="4.14578E-05" ixy="-7.39808E-09" ixz="9.04316E-06" iyy="4.67546E-05" iyz="-6.88155E-09" izz="6.51177E-05" />
    </inertial>
    <visual>
      <origin xyz="0 0 0" rpy="0 0 0" />
      <geometry>
        <mesh filename="meshes/visual/arm_l7.glb" />
      </geometry>
    </visual>
    </link>
  <joint name="R_arm_j7" type="revolute">
    <origin xyz="0.065 0.032 0.0319" rpy="0 0 0" />
    <parent link="R_arm_l6" />
    <child link="R_arm_l7" />
    <axis xyz="0 0 1" />
    <limit lower="-1.117" upper="1.378" effort="25" velocity="2.7" />
  </joint>
  <link name="R_arm_l8">
    <inertial>
      <origin xyz="-0.01782 1.03176E-06 0.00027" rpy="0 0 0" />
      <mass value="0.07431" />
      <inertia ixx="3.42446E-05" ixy="-3.10006E-08" ixz="1.26617E-07" iyy="2.12153E-05" iyz="8.02183E-08" izz="2.10214E-05" />
    </inertial>
    <visual>
      <origin xyz="0 0 0" rpy="0 -1.57079 0" />
      <geometry>
        <mesh filename="meshes/visual/arm_l8.glb" />
      </geometry>
    </visual>
    </link>
  <joint name="R_arm_j8" type="fixed">
    <origin xyz="0.11597 0 -0.032" rpy="0 1.57079 0" />
    <parent link="R_arm_l7" />
    <child link="R_arm_l8" />
    <axis xyz="0 0 0" />
  </joint>
  <link name="R_ee" />
  <joint name="R_ee_j0" type="fixed">
    <origin xyz="0 0 0" rpy="0 0 1.57079" />
    <parent link="R_arm_l8" />
    <child link="R_ee" />
  </joint>

  <link name="lidar">
    <inertial>
      <origin xyz="-0.00548 3.47734E-05 -0.00608" rpy="0 0 0" />
      <mass value="0.00423" />
      <inertia ixx="1.38704E-07" ixy="1.77495E-14" ixz="-1.01452E-10" iyy="1.36178E-07" iyz="-2.22399E-15" izz="1.6409E-07" />
    </inertial>
    <visual>
      <origin xyz="0 0 0" rpy="0 0 0" />
      <geometry>
        <mesh filename="meshes/visual/lidar.glb" />
      </geometry>
    </visual>
  </link>
  <joint name="lidar_mount" type="fixed">
    <origin xyz="0.2975 0 0.144" rpy="0 0 0" />
    <parent link="base" />
    <child link="lidar" />
    <axis xyz="0 0 0" />
  </joint>
  <link name="imu">
    <inertial>
      <origin xyz="6.06827E-05 -5.84386E-18 -0.00788" rpy="0 0 0" />
      <mass value="0.01779" />
      <inertia ixx="2.22862E-06" ixy="-2.07088E-22" ixz="3.66731E-09" iyy="1.97585E-06" iyz="-1.34274E-22" izz="3.49443E-06" />
    </inertial>
    <visual>
      <origin xyz="0 0 0" rpy="0 0 0" />
      <geometry>
        <mesh filename="meshes/visual/imu.glb" />
      </geometry>
    </visual>
  </link>
  <joint name="imu_mount" type="fixed">
    <origin xyz="0.165 0 0.2071" rpy="0 0 0" />
    <parent link="base" />
    <child link="imu" />
    <axis xyz="0 0 0" />
  </joint>
  <link name="L_base_cam">
    <inertial>
      <origin xyz="-0.00857 -2.77556E-17 -0.001" rpy="0 0 0" />
      <mass value="0.00309" />
      <inertia ixx="1.66577E-07" ixy="-1.91034E-23" ixz="1.13265E-23" iyy="9.21398E-08" iyz="8.88173E-24" izz="1.22898E-07" />
    </inertial>
    <visual>
      <origin xyz="0 0 0" rpy="0 0 0" />
      <geometry>
        <mesh filename="meshes/visual/base_cam.glb" />
      </geometry>
    </visual>
  </link>
  <joint name="L_base_cam_mount" type="fixed">
    <origin xyz="0.02 0.2673 0.208" rpy="0 0 1.5708" />
    <parent link="base" />
    <child link="L_base_cam" />
    <axis xyz="0 0 0" />
  </joint>
  <link name="R_base_cam">
    <inertial>
      <origin xyz="-0.00857 2.77556E-17 -0.001" rpy="0 0 0" />
      <mass value="0.00309" />
      <inertia ixx="1.66577E-07" ixy="7.23081E-24" ixz="9.22687E-25" iyy="9.21398E-08" iyz="-1.69205E-22" izz="1.22898E-07" />
    </inertial>
    <visual>
      <origin xyz="0 0 0" rpy="0 0 0" />
      <geometry>
        <mesh filename="meshes/visual/base_cam.glb" />
      </geometry>
    </visual>
  </link>
  <joint name="R_base_cam_mount" type="fixed">
    <origin xyz="0.02 -0.2673 0.208" rpy="0 0 -1.5708" />
    <parent link="base" />
    <child link="R_base_cam" />
    <axis xyz="0 0 0" />
  </joint>
  <link name="F_base_cam">
    <inertial>
      <origin xyz="-0.00857 1.01381E-17 -0.001" rpy="0 0 0" />
      <mass value="0.00309" />
      <inertia ixx="1.66577E-07" ixy="-1.64559E-23" ixz="-6.41597E-24" iyy="9.21398E-08" iyz="1.29109E-22" izz="1.22898E-07" />
    </inertial>
    <visual>
      <origin xyz="0 0 0" rpy="0 0 0" />
      <geometry>
        <mesh filename="meshes/visual/base_cam.glb" />
      </geometry>
    </visual>
  </link>
  <joint name="F_base_cam_mount" type="fixed">
    <origin xyz="0.3373 0 0.208" rpy="0 0 0" />
    <parent link="base" />
    <child link="F_base_cam" />
    <axis xyz="0 0 0" />
  </joint>
  <link name="B_base_cam">
    <inertial>
      <origin xyz="-0.00857 -1.99967E-19 -0.001" rpy="0 0 0" />
      <mass value="0.00309" />
      <inertia ixx="1.66577E-07" ixy="5.77269E-24" ixz="3.0439E-23" iyy="9.21398E-08" iyz="-2.66772E-23" izz="1.22898E-07" />
    </inertial>
    <visual>
      <origin xyz="0 0 0" rpy="0 0 0" />
      <geometry>
        <mesh filename="meshes/visual/base_cam.glb" />
      </geometry>
    </visual>
  </link>
  <joint name="B_base_cam_mount" type="fixed">
    <origin xyz="-0.3303 0 0.176" rpy="0 0 3.1416" />
    <parent link="base" />
    <child link="B_base_cam" />
    <axis xyz="0 0 0" />
  </joint>
  <link name="LF_ultrasonic">
    <inertial>
      <origin xyz="-0.00984 -0.00459 -0.00495" rpy="0 0 0" />
      <mass value="0.01186" />
      <inertia ixx="1.13153E-06" ixy="1.72173E-07" ixz="-8.76866E-08" iyy="8.4259E-07" iyz="-4.08889E-08" izz="1.31676E-06" />
    </inertial>
    <visual>
      <origin xyz="0 0 0" rpy="0 0 0" />
      <geometry>
        <mesh filename="meshes/visual/ultrasonic.glb" />
      </geometry>
    </visual>
  </link>
  <joint name="LF_ultrasonic_mount" type="fixed">
    <origin xyz="0.31642 0.14755 0.15853" rpy="0.01745 -0.41887 0.43633" />
    <parent link="base" />
    <child link="LF_ultrasonic" />
  </joint>
  <link name="RF_ultrasonic">
    <inertial>
      <origin xyz="-0.00984 0.00459 -0.00495" rpy="0 0 0" />
      <mass value="0.01186" />
      <inertia ixx="1.13153E-06" ixy="-1.72173E-07" ixz="-8.76866E-08" iyy="8.4259E-07" iyz="4.08889E-08" izz="1.31676E-06" />
    </inertial>
    <visual>
      <origin xyz="0 0 0" rpy="0 0 0" />
      <geometry>
        <mesh filename="meshes/visual/ultrasonic.glb" />
      </geometry>
    </visual>
  </link>
  <joint name="RF_ultrasonic_mount" type="fixed">
    <origin xyz="0.31642 -0.14755 0.15853" rpy="0.01745 -0.41887 -0.43633" />
    <parent link="base" />
    <child link="RF_ultrasonic" />
    <axis xyz="0 0 0" />
  </joint>
  <link name="LB_ultrasonic">
    <inertial>
      <origin xyz="-0.01193 0 -0.00011" rpy="0 0 0" />
      <mass value="0.01186" />
      <inertia ixx="1.15728E-06" ixy="5.15596E-09" ixz="0" iyy="7.86731E-07" iyz="-1.19495E-07" izz="1.34687E-06" />
    </inertial>
    <visual>
      <origin xyz="0 0 0" rpy="0 0 0" />
      <geometry>
        <mesh filename="meshes/visual/ultrasonic.glb" />
      </geometry>
    </visual>
  </link>
  <joint name="LB_ultrasonic_mount" type="fixed">
    <origin xyz="-0.31633 0.14751 0.07886" rpy="0 -0.45379 2.7053" />
    <parent link="base" />
    <child link="LB_ultrasonic" />
    <axis xyz="0 0 0" />
  </joint>
  <link name="RB_ultrasonic">
    <inertial>
      <origin xyz="-0.01193 0 -0.00011" rpy="0 0 0" />
      <mass value="0.01186" />
      <inertia ixx="1.15728E-06" ixy="5.15596E-09" ixz="0" iyy="7.86731E-07" iyz="-1.19495E-07" izz="1.34687E-06" />
    </inertial>
    <visual>
      <origin xyz="0 0 0" rpy="0 0 0" />
      <geometry>
        <mesh filename="meshes/visual/ultrasonic.glb" />
      </geometry>
    </visual>
  </link>
  <joint name="RB_ultrasonic_mount" type="fixed">
    <origin xyz="-0.31633 -0.14751 0.07886" rpy="0 -0.45379 -2.70526" />
    <parent link="base" />
    <child link="RB_ultrasonic" />
    <axis xyz="0 0 0" />
  </joint>

  <joint name="L_hand_mount" type="fixed">
    <origin xyz="0.00019 0.00390 0.00014" rpy="-1.57079 1.57079 0" />
    <parent link="L_arm_l8" />
    <child link="L_hand_base" />
  </joint>
  <link name="L_hand_base">
    <inertial>
      <origin xyz="-0.04878 0.00248 -0.00378" rpy="0 0 0" />
      <mass value="0.05182" />
      <inertia ixx="1.90439E-05" ixy="9.03565E-07" ixz="1.72176E-06" iyy="2.43366E-05" iyz="4.70654E-07" izz="3.58010E-05" />
    </inertial>
    <visual>
      <origin xyz="0 0 0" rpy="0 0 0" />
      <geometry>
        <mesh filename="../../hands/f5d6_hand/meshes/visual/connector.glb" />
      </geometry>
    </visual>
    <visual>
      <origin xyz="0 0 0" rpy="0 0 0" />
      <geometry>
        <mesh filename="../../hands/f5d6_hand/meshes/visual/L_hand_base.glb" />
      </geometry>
    </visual>
    </link>
  <link name="L_th_l0">
    <inertial>
      <origin xyz="0.00118 0.00613 -0.00211" rpy="0 0 0" />
      <mass value="0.00232" />
      <inertia ixx="1.75839E-07" ixy="5.95523E-08" ixz="-4.97756E-09" iyy="1.47406E-07" iyz="1.16060E-08" izz="1.75736E-07" />
    </inertial>
    <visual>
      <origin xyz="0 0 -0.00580" rpy="3.14159 0 0" />
      <geometry>
        <mesh filename="../../hands/f5d6_hand/meshes/visual/th_l0.glb" />
      </geometry>
    </visual>
    </link>
  <joint name="L_th_j0" type="revolute">
    <origin xyz="-0.04608 0.01984 -0.02684" rpy="0 -0.21841 -0.01325" />
    <parent link="L_hand_base" />
    <child link="L_th_l0" />
    <axis xyz="-1 0 0" />
    <limit lower="-0.0158" upper="1.605" effort="1.0" velocity="6.28" />
  </joint>
  <link name="L_th_l1">
    <inertial>
      <origin xyz="-0.01803 0.00796 -0.00016" rpy="0 0 0" />
      <mass value="0.00666" />
      <inertia ixx="4.79346E-07" ixy="4.90524E-07" ixz="-1.17783E-11" iyy="1.88643E-06" iyz="-5.33955E-11" izz="2.21298E-06" />
    </inertial>
    <visual>
      <origin xyz="0 0 0" rpy="0 0 3.14" />
      <geometry>
        <mesh filename="../../hands/f5d6_hand/meshes/visual/th_l1.glb" />
      </geometry>
    </visual>
    </link>
  <joint name="L_th_j1" type="revolute">
    <origin xyz="-0.00675 0.02098 -0.00270" rpy="0 0 0.01293" />
    <parent link="L_th_l0" />
    <child link="L_th_l1" />
    <axis xyz="0 0 -1" />
    <limit lower="-0.3468" upper="0.1834" effort="1.0" velocity="6.28" />
  </joint>
  <link name="L_th_l2">
    <inertial>
      <origin xyz="-0.00825 0.00781 0.00190" rpy="0 0 0" />
      <mass value="0.00503" />
      <inertia ixx="1.99364E-07" ixy="5.81205E-08" ixz="-5.87916E-12" iyy="2.67949E-07" iyz="1.69508E-12" izz="2.35219E-07" />
    </inertial>
    <visual>
      <origin xyz="0 0 0.00380" rpy="0 0 3.14159" />
      <geometry>
        <mesh filename="../../hands/f5d6_hand/meshes/visual/th_l2.glb" />
      </geometry>
    </visual>
    </link>
  <joint name="L_th_j2" type="revolute">
    <origin xyz="-0.05088 0.01301 -0.00202" rpy="0 0 0" />
    <parent link="L_th_l1" />
    <child link="L_th_l2" />
    <axis xyz="0 0 -1" />
    <limit lower="-0.4298" upper="0.2731" effort="0.5" velocity="6.28" />
    <mimic joint="L_th_j1" multiplier="1.35316" offset="0.00765" />
  </joint>
  <link name="L_ff_l1">
    <inertial>
      <origin xyz="-0.01602 -9.85142E-05 -0.00754" rpy="0 0 0" />
      <mass value="0.00155" />
      <inertia ixx="6.86607E-08" ixy="6.40093E-13" ixz="-2.71260E-08" iyy="1.54822E-07" iyz="2.47486E-12" izz="1.62362E-07" />
    </inertial>
    <visual>
      <origin xyz="0 0 0" rpy="0 0 0" />
      <geometry>
        <mesh filename="../../hands/f5d6_hand/meshes/visual/ff_l1.glb" />
      </geometry>
    </visual>
    </link>
  <joint name="L_ff_j1" type="revolute">
    <origin xyz="-0.11269 0.03067 -0.00116" rpy="-0.08731 -0.00723 -0.08240" />
    <parent link="L_hand_base" />
    <child link="L_ff_l1" />
    <axis xyz="0 1 0" />
    <limit lower="-1.0946" upper="0.2891" effort="0.5" velocity="6.28" />
  </joint>
  <link name="L_ff_l2">
    <inertial>
      <origin xyz="-0.01405 -9.47216E-05 -0.01877" rpy="0 0 0" />
      <mass value="0.00416" />
      <inertia ixx="3.83569E-07" ixy="3.63725E-12" ixz="-2.50539E-07" iyy="5.74333E-07" iyz="5.30246E-12" izz="2.66485E-07" />
    </inertial>
    <visual>
      <origin xyz="0 0 0" rpy="0 0 0" />
      <geometry>
        <mesh filename="../../hands/f5d6_hand/meshes/visual/ff_l2.glb" />
      </geometry>
    </visual>
    </link>
  <joint name="L_ff_j2" type="revolute">
    <origin xyz="-0.03406 0 -0.01141" rpy="0 0 -0.00010" />
    <parent link="L_ff_l1" />
    <child link="L_ff_l2" />
    <axis xyz="0 1 0" />
    <limit lower="-1.2101" upper="0.3681" effort="0.5" velocity="6.28" />
    <mimic joint="L_ff_j1" multiplier="1.13028" offset="-0.00053" />
  </joint>
  <link name="L_mf_l1">
    <inertial>
      <origin xyz="0.03832 -0.00051 -0.01587" rpy="0 0 0" />
      <mass value="0.10211" />
      <inertia ixx="9.82031E-05" ixy="4.89564E-06" ixz="-3.61758E-05" iyy="2.71614E-04" iyz="2.12856E-05" izz="3.10529E-04" />
    </inertial>
    <visual>
      <origin xyz="0 0 0" rpy="0 0 0" />
      <geometry>
        <mesh filename="../../hands/f5d6_hand/meshes/visual/mf_l1.glb" />
      </geometry>
    </visual>
    </link>
  <joint name="L_mf_j1" type="revolute">
    <origin xyz="-0.11597 0.01047 0.00314" rpy="0 0 -0.01325" />
    <parent link="L_hand_base" />
    <child link="L_mf_l1" />
    <axis xyz="0 1 0" />
    <limit lower="-1.0844" upper="0.2801" effort="0.5" velocity="6.28" />
  </joint>
  <link name="L_mf_l2">
    <inertial>
      <origin xyz="-0.01427 9.50657E-05 -0.01861" rpy="0 0 0" />
      <mass value="0.00416" />
      <inertia ixx="3.77813E-07" ixy="2.94200E-12" ixz="-2.51812E-07" iyy="5.74328E-07" iyz="4.24957E-12" izz="2.72236E-07" />
    </inertial>
    <visual>
      <origin xyz="0 0 0" rpy="0 0 0" />
      <geometry>
        <mesh filename="../../hands/f5d6_hand/meshes/visual/mf_l2.glb" />
      </geometry>
    </visual>
    </link>
  <joint name="L_mf_j2" type="revolute">
    <origin xyz="-0.03829 0 -0.01467" rpy="0 0 0" />
    <parent link="L_mf_l1" />
    <child link="L_mf_l2" />
    <axis xyz="0 1 0" />
    <limit lower="-1.2026" upper="0.3533" effort="0.5" velocity="6.28" />
    <mimic joint="L_mf_j1" multiplier="1.13311" offset="-0.00079" />
  </joint>
  <link name="L_rf_l1">
    <inertial>
      <origin xyz="-0.01575 -9.85177E-05 -0.00809" rpy="0 0 0" />
      <mass value="0.00155" />
      <inertia ixx="7.06600E-08" ixy="9.80912E-13" ixz="-3.03177E-08" iyy="1.54825E-07" iyz="2.70998E-12" izz="1.60367E-07" />
    </inertial>
    <visual>
      <origin xyz="0 0 0" rpy="0 0 0" />
      <geometry>
        <mesh filename="../../hands/f5d6_hand/meshes/visual/rf_l1.glb" />
      </geometry>
    </visual>
    </link>
  <joint name="L_rf_j1" type="revolute">
    <origin xyz="-0.11324 -0.00937 0.00239" rpy="0 0 0.05660" />
    <parent link="L_hand_base" />
    <child link="L_rf_l1" />
    <axis xyz="0 1 0" />
    <limit lower="-1.0154" upper="0.2840" effort="0.5" velocity="6.28" />
  </joint>
  <link name="L_rf_l2">
    <inertial>
      <origin xyz="-0.01273 -9.38053E-05 -0.01968" rpy="0 0 0" />
      <mass value="0.00416" />
      <inertia ixx="4.17201E-07" ixy="-1.25235E-12" ixz="-2.40009E-07" iyy="5.74059E-07" iyz="-5.32327E-12" izz="2.32587E-07" />
    </inertial>
    <visual>
      <origin xyz="0 0 0" rpy="0 0 0" />
      <geometry>
        <mesh filename="../../hands/f5d6_hand/meshes/visual/rf_l2.glb" />
      </geometry>
    </visual>
    </link>
  <joint name="L_rf_j2" type="revolute">
    <origin xyz="-0.03364 0 -0.01258" rpy="0 0 -0.00010" />
    <parent link="L_rf_l1" />
    <child link="L_rf_l2" />
    <axis xyz="0 1 0" />
    <limit lower="-1.1156" upper="0.3599" effort="0.5" velocity="6.28" />
    <mimic joint="L_rf_j1" multiplier="1.12935" offset="0.00065" />
  </joint>
  <link name="L_lf_l1">
    <inertial>
      <origin xyz="-0.01409 0.00010 -0.00740" rpy="0 0 0" />
      <mass value="0.00137" />
      <inertia ixx="6.23124E-08" ixy="-5.30007E-13" ixz="-2.07729E-08" iyy="1.12813E-07" iyz="-3.85122E-13" izz="1.20866E-07" />
    </inertial>
    <visual>
      <origin xyz="0 0 0" rpy="0 0 0" />
      <geometry>
        <mesh filename="../../hands/f5d6_hand/meshes/visual/lf_l1.glb" />
      </geometry>
    </visual>
    </link>
  <joint name="L_lf_j1" type="revolute">
    <origin xyz="-0.10947 -0.02964 -0.00017" rpy="0.08722 -0.01033 0.11755" />
    <parent link="L_hand_base" />
    <child link="L_lf_l1" />
    <axis xyz="0 1 0" />
    <limit lower="-1.0118" upper="0.2811" effort="0.5" velocity="6.28" />
  </joint>
  <link name="L_lf_l2">
    <inertial>
      <origin xyz="-0.00835 -0.00012 -0.01408" rpy="0 0 0" />
      <mass value="0.00263" />
      <inertia ixx="1.24027E-07" ixy="-6.08327E-10" ixz="-5.50957E-08" iyy="1.53210E-07" iyz="-1.07170E-09" izz="7.25224E-08" />
    </inertial>
    <visual>
      <origin xyz="0 0 0" rpy="0 0 0" />
      <geometry>
        <mesh filename="../../hands/f5d6_hand/meshes/visual/lf_l2.glb" />
      </geometry>
    </visual>
    </link>
  <joint name="L_lf_j2" type="revolute">
    <origin xyz="-0.02974 5.03150E-05 -0.01163" rpy="2.10550E-05 0 0" />
    <parent link="L_lf_l1" />
    <child link="L_lf_l2" />
    <axis xyz="0 1 0" />
    <limit lower="-1.1073" upper="0.4014" effort="0.5" velocity="6.28" />
    <mimic joint="L_lf_j1" multiplier="1.15037" offset="0.00186" />
  </joint>

  <link name="L_th_tip" />
  <joint name="L_th_tip_j0" type="fixed">
    <origin xyz="-0.0230 0.0151 0.0018" rpy="0 0 0" />
    <parent link="L_th_l2" />
    <child link="L_th_tip" />
  </joint>
  <link name="L_ff_tip" />
  <joint name="L_ff_tip_j0" type="fixed">
    <origin xyz="-0.0300 0.0 -0.0400" rpy="0 0 0" />
    <parent link="L_ff_l2" />
    <child link="L_ff_tip" />
  </joint>
  <link name="L_mf_tip" />
  <joint name="L_mf_tip_j0" type="fixed">
    <origin xyz="-0.0304 0.0 -0.0397" rpy="0 0 0" />
    <parent link="L_mf_l2" />
    <child link="L_mf_tip" />
  </joint>
  <link name="L_rf_tip" />
  <joint name="L_rf_tip_j0" type="fixed">
    <origin xyz="-0.0272 0 -0.0420" rpy="0 0 0" />
    <parent link="L_rf_l2" />
    <child link="L_rf_tip" />
  </joint>
  <link name="L_lf_tip" />
  <joint name="L_lf_tip_j0" type="fixed">
    <origin xyz="-0.0182 0 -0.0306" rpy="0 0 0" />
    <parent link="L_lf_l2" />
    <child link="L_lf_tip" />
  </joint>


  <joint name="R_hand_mount" type="fixed">
    <origin xyz="0.00019 -0.00390 0.00014" rpy="1.57079 1.57079 0" />
    <parent link="R_arm_l8" />
    <child link="R_hand_base" />
  </joint>
  <link name="R_hand_base">
    <inertial>
      <origin xyz="-0.04133 -0.00272 -0.00667" rpy="0 0 0" />
      <mass value="0.03659" />
      <inertia ixx="1.14586E-05" ixy="-1.17421E-06" ixz="8.02063E-07" iyy="9.13975E-06" iyz="-2.84474E-07" izz="1.41942E-05" />
    </inertial>
    <visual>
      <origin xyz="0 0 0" rpy="0 0 0" />
      <geometry>
        <mesh filename="../../hands/f5d6_hand/meshes/visual/connector.glb" />
      </geometry>
    </visual>
    <visual>
      <origin xyz="0 0 0" rpy="0 0 0" />
      <geometry>
        <mesh filename="../../hands/f5d6_hand/meshes/visual/R_hand_base.glb" />
      </geometry>
    </visual>
    </link>
  <link name="R_th_l0">
    <inertial>
      <origin xyz="0.00118 -0.00613 -0.00213" rpy="0 0 0" />
      <mass value="0.00232" />
      <inertia ixx="1.75838E-07" ixy="-5.95375E-08" ixz="-5.14845E-09" iyy="1.47472E-07" iyz="-1.16870E-08" izz="1.75668E-07" />
    </inertial>
    <visual>
      <origin xyz="0 0 0" rpy="0 0 0" />
      <geometry>
        <mesh filename="../../hands/f5d6_hand/meshes/visual/th_l0.glb" />
      </geometry>
    </visual>
    </link>
  <joint name="R_th_j0" type="revolute">
    <origin xyz="-0.04608 -0.01984 -0.02687" rpy="-0.00287 -0.21841 0.01325" />
    <parent link="R_hand_base" />
    <child link="R_th_l0" />
    <axis xyz="1 0 0" />
    <limit lower="-0.0158" upper="1.605" effort="1.0" velocity="6.28" />
  </joint>
  <link name="R_th_l1">
    <inertial>
      <origin xyz="0.01732 -0.00805 -0.00337" rpy="0 0 0" />
      <mass value="0.00416" />
      <inertia ixx="2.66072E-07" ixy="2.70383E-07" ixz="-2.29989E-08" iyy="1.00883E-06" iyz="1.70663E-08" izz="1.17421E-06" />
    </inertial>
    <visual>
      <origin xyz="0 0 0" rpy="0 0 0" />
      <geometry>
        <mesh filename="../../hands/f5d6_hand/meshes/visual/th_l1.glb" />
      </geometry>
    </visual>
    </link>
  <joint name="R_th_j1" type="revolute">
    <origin xyz="-0.00675 -0.02097 -0.00276" rpy="3.13870 -0.00004 3.12870" />
    <parent link="R_th_l0" />
    <child link="R_th_l1" />
    <axis xyz="0 0 -1" />
    <limit lower="-0.3468" upper="0.1834" effort="1.0" velocity="6.28" />
  </joint>
  <link name="R_th_l2">
    <inertial>
      <origin xyz="0.00825 -0.00781 -0.00190" rpy="0 0 0" />
      <mass value="0.00503" />
      <inertia ixx="1.99369E-07" ixy="5.81238E-08" ixz="-6.38608E-12" iyy="2.67971E-07" iyz="-8.07033E-13" izz="2.35242E-07" />
    </inertial>
    <visual>
      <origin xyz="0 0 0" rpy="0 0 0" />
      <geometry>
        <mesh filename="../../hands/f5d6_hand/meshes/visual/th_l2.glb" />
      </geometry>
    </visual>
    </link>
  <joint name="R_th_j2" type="revolute">
    <origin xyz="0.05088 -0.01301 0.00202" rpy="0 0 0" />
    <parent link="R_th_l1" />
    <child link="R_th_l2" />
    <axis xyz="0 0 -1" />
    <limit lower="-0.4298" upper="0.2731" effort="0.5" velocity="6.28" />
    <mimic joint="R_th_j1" multiplier="1.35316" offset="0.00765" />
  </joint>
  <link name="R_ff_l1">
    <inertial>
      <origin xyz="-0.01602 0.00010 -0.00754" rpy="0 0 0" />
      <mass value="0.00155" />
      <inertia ixx="6.86667E-08" ixy="-5.82417E-12" ixz="-2.71301E-08" iyy="1.54849E-07" iyz="7.16927E-13" izz="1.62393E-07" />
    </inertial>
    <visual>
      <origin xyz="0 0 0" rpy="0 0 0" />
      <geometry>
        <mesh filename="../../hands/f5d6_hand/meshes/visual/ff_l1.glb" />
      </geometry>
    </visual>
    </link>
  <joint name="R_ff_j1" type="revolute">
    <origin xyz="-0.11269 -0.03066 -0.00119" rpy="0.08731 -0.00723 0.08240" />
    <parent link="R_hand_base" />
    <child link="R_ff_l1" />
    <axis xyz="0 1 0" />
    <limit lower="-1.0946" upper="0.2891" effort="0.5" velocity="6.28" />
  </joint>
  <link name="R_ff_l2">
    <inertial>
      <origin xyz="-0.01405 0.00009 -0.01877" rpy="0 0 0" />
      <mass value="0.00416" />
      <inertia ixx="3.83689E-07" ixy="3.50584E-13" ixz="-2.50617E-07" iyy="5.74504E-07" iyz="3.75938E-12" izz="2.66541E-07" />
    </inertial>
    <visual>
      <origin xyz="0 0 0" rpy="0 0 0" />
      <geometry>
        <mesh filename="../../hands/f5d6_hand/meshes/visual/ff_l2.glb" />
      </geometry>
    </visual>
    </link>
  <joint name="R_ff_j2" type="revolute">
    <origin xyz="-0.03406 0 -0.01141" rpy="-0.00003 0 0.00010" />
    <parent link="R_ff_l1" />
    <child link="R_ff_l2" />
    <axis xyz="0 1 0" />
    <limit lower="-1.2101" upper="0.3681" effort="0.5" velocity="6.28" />
    <mimic joint="R_ff_j1" multiplier="1.13028" offset="-0.00053" />
  </joint>
  <link name="R_mf_l1">
    <inertial>
      <origin xyz="-0.01788 -0.00010 -0.00978" rpy="0 0 0" />
      <mass value="0.00190" />
      <inertia ixx="9.59615E-08" ixy="1.38745E-12" ixz="-5.32051E-08" iyy="2.34143E-07" iyz="2.76724E-12" izz="2.28131E-07" />
    </inertial>
    <visual>
      <origin xyz="0 0 0" rpy="0 0 0" />
      <geometry>
        <mesh filename="../../hands/f5d6_hand/meshes/visual/mf_l1.glb" />
      </geometry>
    </visual>
    </link>
  <joint name="R_mf_j1" type="revolute">
    <origin xyz="-0.11597 -0.01047 0.00312" rpy="0 0 0.01325" />
    <parent link="R_hand_base" />
    <child link="R_mf_l1" />
    <axis xyz="0 1 0" />
    <limit lower="-1.0844" upper="0.2801" effort="0.5" velocity="6.28" />
  </joint>
  <link name="R_mf_l2">
    <inertial>
      <origin xyz="-0.01427 -0.00009 -0.01861" rpy="0 0 0" />
      <mass value="0.00416" />
      <inertia ixx="3.77923E-07" ixy="1.47250E-12" ixz="-2.51884E-07" iyy="5.74486E-07" iyz="5.20497E-12" izz="2.72289E-07" />
    </inertial>
    <visual>
      <origin xyz="0 0 0" rpy="0 0 0" />
      <geometry>
        <mesh filename="../../hands/f5d6_hand/meshes/visual/mf_l2.glb" />
      </geometry>
    </visual>
    </link>
  <joint name="R_mf_j2" type="revolute">
    <origin xyz="-0.03829 0 -0.01467" rpy="0 0 0" />
    <parent link="R_mf_l1" />
    <child link="R_mf_l2" />
    <axis xyz="0 1 0" />
    <limit lower="-1.2026" upper="0.3533" effort="0.5" velocity="6.28" />
    <mimic joint="R_mf_j1" multiplier="1.13311" offset="-0.00079" />
  </joint>
  <link name="R_rf_l1">
    <inertial>
      <origin xyz="-0.01575 0.00010 -0.00809" rpy="0 0 0" />
      <mass value="0.00155" />
      <inertia ixx="7.06660E-08" ixy="-6.33539E-12" ixz="-3.03213E-08" iyy="1.54849E-07" iyz="3.51578E-13" izz="1.60394E-07" />
    </inertial>
    <visual>
      <origin xyz="0 0 0" rpy="0 0 0" />
      <geometry>
        <mesh filename="../../hands/f5d6_hand/meshes/visual/rf_l1.glb" />
      </geometry>
    </visual>
    </link>
  <joint name="R_rf_j1" type="revolute">
    <origin xyz="-0.11324 0.00937 0.00237" rpy="0 0 -0.05660" />
    <parent link="R_hand_base" />
    <child link="R_rf_l1" />
    <axis xyz="0 1 0" />
    <limit lower="-1.0154" upper="0.2840" effort="0.5" velocity="6.28" />
  </joint>
  <link name="R_rf_l2">
    <inertial>
      <origin xyz="-0.01273 0.00009 -0.01968" rpy="0 0 0" />
      <mass value="0.00416" />
      <inertia ixx="4.17200E-07" ixy="-5.15153E-12" ixz="-2.40011E-07" iyy="5.74060E-07" iyz="-8.77895E-12" izz="2.32592E-07" />
    </inertial>
    <visual>
      <origin xyz="0 0 0" rpy="0 0 0" />
      <geometry>
        <mesh filename="../../hands/f5d6_hand/meshes/visual/rf_l2.glb" />
      </geometry>
    </visual>
    </link>
  <joint name="R_rf_j2" type="revolute">
    <origin xyz="-0.03364 0 -0.01258" rpy="-0.00003 0 0.00010" />
    <parent link="R_rf_l1" />
    <child link="R_rf_l2" />
    <axis xyz="0 1 0" />
    <limit lower="-1.1156" upper="0.3599" effort="0.5" velocity="6.28" />
    <mimic joint="R_rf_j1" multiplier="1.12935" offset="0.00065" />
  </joint>
  <link name="R_lf_l1">
    <inertial>
      <origin xyz="-0.01409 -0.00010 -0.00740" rpy="0 0 0" />
      <mass value="0.00137" />
      <inertia ixx="6.23133E-08" ixy="-5.93152E-13" ixz="-2.07711E-08" iyy="1.12814E-07" iyz="1.56840E-13" izz="1.20863E-07" />
    </inertial>
    <visual>
      <origin xyz="0 0 0" rpy="0 0 0" />
      <geometry>
        <mesh filename="../../hands/f5d6_hand/meshes/visual/lf_l1.glb" />
      </geometry>
    </visual>
    </link>
  <joint name="R_lf_j1" type="revolute">
    <origin xyz="-0.10947 0.02964 -0.00019" rpy="-0.08722 -0.01033 -0.11755" />
    <parent link="R_hand_base" />
    <child link="R_lf_l1" />
    <axis xyz="0 1 0" />
    <limit lower="-1.0118" upper="0.2811" effort="0.5" velocity="6.28" />
  </joint>
  <link name="R_lf_l2">
    <inertial>
      <origin xyz="-0.00835 0.00012 -0.01408" rpy="0 0 0" />
      <mass value="0.00263" />
      <inertia ixx="1.24022E-07" ixy="6.09239E-10" ixz="-5.50999E-08" iyy="1.53209E-07" iyz="1.06950E-09" izz="7.25262E-08" />
    </inertial>
    <visual>
      <origin xyz="0 0 0" rpy="0 0 0" />
      <geometry>
        <mesh filename="../../hands/f5d6_hand/meshes/visual/lf_l2.glb" />
      </geometry>
    </visual>
    </link>
  <joint name="R_lf_j2" type="revolute">
    <origin xyz="-0.02974 -0.00005 -0.01163" rpy="-0.00002 0 0" />
    <parent link="R_lf_l1" />
    <child link="R_lf_l2" />
    <axis xyz="0 1 0" />
    <limit lower="-1.1073" upper="0.4014" effort="0.5" velocity="6.28" />
    <mimic joint="R_lf_j1" multiplier="1.15037" offset="0.00186" />
  </joint>

  <link name="R_th_tip" />
  <joint name="R_th_tip_j0" type="fixed">
    <origin xyz="0.0230 -0.0151 -0.0018" rpy="0 0 0" />
    <parent link="R_th_l2" />
    <child link="R_th_tip" />
  </joint>
  <link name="R_ff_tip" />
  <joint name="R_ff_tip_j0" type="fixed">
    <origin xyz="-0.0300 0.0 -0.0400" rpy="0 0 0" />
    <parent link="R_ff_l2" />
    <child link="R_ff_tip" />
  </joint>
  <link name="R_mf_tip" />
  <joint name="R_mf_tip_j0" type="fixed">
    <origin xyz="-0.0304 0.0 -0.0397" rpy="0 0 0" />
    <parent link="R_mf_l2" />
    <child link="R_mf_tip" />
  </joint>
  <link name="R_rf_tip" />
  <joint name="R_rf_tip_j0" type="fixed">
    <origin xyz="-0.0272 0 -0.0420" rpy="0 0 0" />
    <parent link="R_rf_l2" />
    <child link="R_rf_tip" />
  </joint>
  <link name="R_lf_tip" />
  <joint name="R_lf_tip_j0" type="fixed">
    <origin xyz="-0.0182 0 -0.0306" rpy="0 0 0" />
    <parent link="R_lf_l2" />
    <child link="R_lf_tip" />
  </joint>
</robot>